Workbook

Sheet Instructions
A1: NIFTY Sector Performance Tracker
A2: A live-recalculating workbook for tracking sector and stock performance across Daily / Weekly / Monthly timeframes.
A4: HOW THIS WORKBOOK STAYS "LIVE"
A5: This workbook does not have a broker/data API wired in yet, so it can't pull prices on its own.
A6: Instead, every calculation (percent change, ranks, best/worst, sector rollups) recalculates instantly
A7: the moment you paste in new numbers — so refreshing is just: paste prices, done.
A9: WHAT TO PASTE, AND WHERE
A10: 1. 'Sector Summary' tab: paste each sector index's current level into the LTP column, as often as you like.
A11: 2. 'Constituents' tab: paste each stock's current price into the LTP column, as often as you like.
A12: 3. Once a day (or once a week/month), refresh the reference closes: 'Prev Close (D)' at the start of each
A13: trading day, 'Prev Close (W)' at the start of each week, 'Prev Close (M)' at the start of each month.
A15: COLOR LEGEND
... A35: has sample stock prices filled in — every other sector's cells are at 0 until you paste real numbers.

Sheet Sector Summary
A1: Active Timeframe: | B1: Daily | C1: <- choose the timeframe for the whole workbook
A3: Sector | B3: Index Symbol | C3: Prev Close (D) | D3: Prev Close (W) | E3: Prev Close (M) | F3: LTP | G3: % Chg (Active) | H3: Rank | I3: Tag
A4: Bank | B4: NIFTYBANK | C4: 52340 | D4: 51820 | E4: 50900 | F4: 52810 | G4: =IFERROR(IF($B$1="Daily",F4/C4-1,IF($B$1="Weekly",F4/D4-1,F4/E4-1)),"") -> 0.0089797478 | H4: =IFERROR(SUMPRODUCT(($G$4:$G$14>G4)*1)+1,"") -> 5 | I4: =IF(H4=1,"Top",IF(H4=11,"Bottom",""))
A5: IT | B5: CNXIT | C5: 38420 | D5: 38900 | E5: 39750 | F5: 38050 | G5: =IFERROR(IF($B$1="Daily",F5/C5-1,IF($B$1="Weekly",F5/D5-1,F5/E5-1)),"") -> -0.0096304008 | H5: =IFERROR(SUMPRODUCT(($G$4:$G$14>G5)*1)+1,"") -> 10 | I5: =IF(H5=1,"Top",IF(H5=11,"Bottom",""))
A6: Auto | B6: CNXAUTO | C6: 24680 | D6: 24310 | E6: 23890 | F6: 24990 | G6: =IFERROR(IF($B$1="Daily",F6/C6-1,IF($B$1="Weekly",F6/D6-1,F6/E6-1)),"") -> 0.012560778 | H6: =IFERROR(SUMPRODUCT(($G$4:$G$14>G6)*1)+1,"") -> 1 | I6: =IF(H6=1,"Top",IF(H6=11,"Bottom","")) -> Top
A7: Pharma | B7: CNXPHARMA | C7: 21540 | D7: 21200 | E7: 20680 | F7: 21790 | G7: =IFERROR(IF($B$1="Daily",F7/C7-1,IF($B$1="Weekly",F7/D7-1,F7/E7-1)),"") -> 0.011606314 | H7: =IFERROR(SUMPRODUCT(($G$4:$G$14>G7)*1)+1,"") -> 2 | I7: =IF(H7=1,"Top",IF(H7=11,"Bottom",""))
A8: FMCG | B8: CNXFMCG | C8: 58900 | D8: 58600 | E8: 58100 | F8: 58750 | G8: =IFERROR(IF($B$1="Daily",F8/C8-1,IF($B$1="Weekly",F8/D8-1,F8/E8-1)),"") -> -0.0025466893 | H8: =IFERROR(SUMPRODUCT(($G$4:$G$14>G8)*1)+1,"") -> 8 | I8: =IF(H8=1,"Top",IF(H8=11,"Bottom",""))
A9: Metal | B9: CNXMETAL | C9: 9820 | D9: 9640 | E9: 9410 | F9: 9905 | G9: =IFERROR(IF($B$1="Daily",F9/C9-1,IF($B$1="Weekly",F9/D9-1,F9/E9-1)),"") -> 0.0086558045 | H9: =IFERROR(SUMPRODUCT(($G$4:$G$14>G9)*1)+1,"") -> 6 | I9: =IF(H9=1,"Top",IF(H9=11,"Bottom",""))
A10: Energy | B10: CNXENERGY | C10: 43210 | D10: 42980 | E10: 42500 | F10: 43080 | G10: =IFERROR(IF($B$1="Daily",F10/C10-1,IF($B$1="Weekly",F10/D10-1,F10/E10-1)),"") -> -0.0030085628 | H10: =IFERROR(SUMPRODUCT(($G$4:$G$14>G10)*1)+1,"") -> 9 | I10: =IF(H10=1,"Top",IF(H10=11,"Bottom",""))
A11: Realty | B11: CNXREALTY | C11: 1120 | D11: 1095 | E11: 1060 | F11: 1132 | G11: =IFERROR(IF($B$1="Daily",F11/C11-1,IF($B$1="Weekly",F11/D11-1,F11/E11-1)),"") -> 0.010714286 | H11: =IFERROR(SUMPRODUCT(($G$4:$G$14>G11)*1)+1,"") -> 3 | I11: =IF(H11=1,"Top",IF(H11=11,"Bottom",""))
A12: Media | B12: CNXMEDIA | C12: 1780 | D12: 1820 | E12: 1890 | F12: 1755 | G12: =IFERROR(IF($B$1="Daily",F12/C12-1,IF($B$1="Weekly",F12/D12-1,F12/E12-1)),"") -> -0.014044944 | H12: =IFERROR(SUMPRODUCT(($G$4:$G$14>G12)*1)+1,"") -> 11 | I12: =IF(H12=1,"Top",IF(H12=11,"Bottom","")) -> Bottom
A13: PSU Bank | B13: NIFTYPSUBANK | C13: 7120 | D13: 6980 | E13: 6810 | F13: 7195 | G13: =IFERROR(IF($B$1="Daily",F13/C13-1,IF($B$1="Weekly",F13/D13-1,F13/E13-1)),"") -> 0.010533708 | H13: =IFERROR(SUMPRODUCT(($G$4:$G$14>G13)*1)+1,"") -> 4 | I13: =IF(H13=1,"Top",IF(H13=11,"Bottom",""))
A14: Fin Service | B14: CNXFINANCE | C14: 23980 | D14: 23750 | E14: 23300 | F14: 24140 | G14: =IFERROR(IF($B$1="Daily",F14/C14-1,IF($B$1="Weekly",F14/D14-1,F14/E14-1)),"") -> 0.0066722269 | H14: =IFERROR(SUMPRODUCT(($G$4:$G$14>G14)*1)+1,"") -> 7 | I14: =IF(H14=1,"Top",IF(H14=11,"Bottom",""))

Sheet Constituents
A1: Sector | B1: Symbol | C1: Prev Close (D) | D1: Prev Close (W) | E1: Prev Close (M) | F1: LTP | G1: % Chg (Active) | H1: Rank in Sector | I1: Key
A2: Bank | B2: HDFCBANK | C2: 1648.2 | D2: 1631.5 | E2: 1602 | F2: 1657.85 | G2: =IFERROR(IF('Sector Summary'!$B$1="Daily",F2/C2-1,IF('Sector Summary'!$B$1="Weekly",F2/D2-1,F2/E2-1)),"") -> 0.005854872 | H2: =IFERROR(SUMPRODUCT(($A$2:$A$13=A2)*($G$2:$G$13>G2))+1,"") -> 10 | I2: =A2&"|"&H2 -> Bank|10
A3: Bank | B3: ICICIBANK | C3: 1211.4 | D3: 1198.75 | E3: 1175.3 | F3: 1223.6 | G3: =IFERROR(IF('Sector Summary'!$B$1="Daily",F3/C3-1,IF('Sector Summary'!$B$1="Weekly",F3/D3-1,F3/E3-1)),"") -> 0.010070992 | H3: =IFERROR(SUMPRODUCT(($A$2:$A$13=A3)*($G$2:$G$13>G3))+1,"") -> 7 | I3: =A3&"|"&H3 -> Bank|7
A4: Bank | B4: SBIN | C4: 818.35 | D4: 805.1 | E4: 792.6 | F4: 826.9 | G4: =IFERROR(IF('Sector Summary'!$B$1="Daily",F4/C4-1,IF('Sector Summary'!$B$1="Weekly",F4/D4-1,F4/E4-1)),"") -> 0.010447852 | H4: =IFERROR(SUMPRODUCT(($A$2:$A$13=A4)*($G$2:$G$13>G4))+1,"") -> 6 | I4: =A4&"|"&H4 -> Bank|6
A5: Bank | B5: KOTAKBANK | C5: 1789.6 | D5: 1802.4 | E5: 1755.9 | F5: 1771.25 | G5: =IFERROR(IF('Sector Summary'!$B$1="Daily",F5/C5-1,IF('Sector Summary'!$B$1="Weekly",F5/D5-1,F5/E5-1)),"") -> -0.010253688 | H5: =IFERROR(SUMPRODUCT(($A$2:$A$13=A5)*($G$2:$G$13>G5))+1,"") -> 11 | I5: =A5&"|"&H5 -> Bank|11
A6: Bank | B6: AXISBANK | C6: 1152.8 | D6: 1140.2 | E6: 1121.4 | F6: 1163.55 | G6: =IFERROR(IF('Sector Summary'!$B$1="Daily",F6/C6-1,IF('Sector Summary'!$B$1="Weekly",F6/D6-1,F6/E6-1)),"") -> 0.0093251214 | H6: =IFERROR(SUMPRODUCT(($A$2:$A$13=A6)*($G$2:$G$13>G6))+1,"") -> 9 | I6: =A6&"|"&H6 -> Bank|9
A7: Bank | B7: INDUSINDBK | C7: 1012.4 | D7: 1035.6 | E7: 1078.2 | F7: 998.1 | G7: =IFERROR(IF('Sector Summary'!$B$1="Daily",F7/C7-1,IF('Sector Summary'!$B$1="Weekly",F7/D7-1,F7/E7-1)),"") -> -0.014124852 | H7: =IFERROR(SUMPRODUCT(($A$2:$A$13=A7)*($G$2:$G$13>G7))+1,"") -> 12 | I7: =A7&"|"&H7 -> Bank|12
A8: Bank | B8: BANKBARODA | C8: 238.15 | D8: 234.8 | E8: 229.4 | F8: 240.9 | G8: =IFERROR(IF('Sector Summary'!$B$1="Daily",F8/C8-1,IF('Sector Summary'!$B$1="Weekly",F8/D8-1,F8/E8-1)),"") -> 0.011547344 | H8: =IFERROR(SUMPRODUCT(($A$2:$A$13=A8)*($G$2:$G$13>G8))+1,"") -> 5 | I8: =A8&"|"&H8 -> Bank|5
A9: Bank | B9: PNB | C9: 102.35 | D9: 100.9 | E9: 98.6 | F9: 103.75 | G9: =IFERROR(IF('Sector Summary'!$B$1="Daily",F9/C9-1,IF('Sector Summary'!$B$1="Weekly",F9/D9-1,F9/E9-1)),"") -> 0.013678554 | H9: =IFERROR(SUMPRODUCT(($A$2:$A$13=A9)*($G$2:$G$13>G9))+1,"") -> 1 | I9: =A9&"|"&H9 -> Bank|1
A10: Bank | B10: IDFCFIRSTB | C10: 72.4 | D10: 71.2 | E10: 69.8 | F10: 73.1 | G10: =IFERROR(IF('Sector Summary'!$B$1="Daily",F10/C10-1,IF('Sector Summary'!$B$1="Weekly",F10/D10-1,F10/E10-1)),"") -> 0.0096685083 | H10: =IFERROR(SUMPRODUCT(($A$2:$A$13=A10)*($G$2:$G$13>G10))+1,"") -> 8 | I10: =A10&"|"&H10 -> Bank|8
A11: Bank | B11: AUBANK | C11: 642.5 | D11: 635.1 | E11: 621.3 | F11: 651.2 | G11: =IFERROR(IF('Sector Summary'!$B$1="Daily",F11/C11-1,IF('Sector Summary'!$B$1="Weekly",F11/D11-1,F11/E11-1)),"") -> 0.013540856 | H11: =IFERROR(SUMPRODUCT(($A$2:$A$13=A11)*($G$2:$G$13>G11))+1,"") -> 2 | I11: =A11&"|"&H11 -> Bank|2
A12: Bank | B12: FEDERALBNK | C12: 196.7 | D12: 193.4 | E12: 189.1 | F12: 199.3 | G12: =IFERROR(IF('Sector Summary'!$B$1="Daily",F12/C12-1,IF('Sector Summary'!$B$1="Weekly",F12/D12-1,F12/E12-1)),"") -> 0.013218099 | H12: =IFERROR(SUMPRODUCT(($A$2:$A$13=A12)*($G$2:$G$13>G12))+1,"") -> 3 | I12: =A12&"|"&H12 -> Bank|3
A13: Bank | B13: CANBK | C13: 98.6 | D13: 96.8 | E13: 94.2 | F13: 99.9 | G13: =IFERROR(IF('Sector Summary'!$B$1="Daily",F13/C13-1,IF('Sector Summary'!$B$1="Weekly",F13/D13-1,F13/E13-1)),"") -> 0.013184584 | H13: =IFERROR(SUMPRODUCT(($A$2:$A$13=A13)*($G$2:$G$13>G13))+1,"") -> 4 | I13: =A13&"|"&H13 -> Bank|4
A14: IT | B14: TCS | C14: 0 | D14: 0 | E14: 0 | F14: 0 | G14: =IFERROR(IF('Sector Summary'!$B$1="Daily",F14/C14-1,IF('Sector Summary'!$B$1="Weekly",F14/D14-1,F14/E14-1)),"") | H14: =IFERROR(SUMPRODUCT(($A$14:$A$23=A14)*($G$14:$G$23>G14))+1,"") -> 1 | I14: =A14&"|"&H14 -> IT|1
A15: IT | B15: INFY | C15: 0 | D15: 0 | E15: 0 | F15: 0 | G15: =IFERROR(IF('Sector Summary'!$B$1="Daily",F15/C15-1,IF('Sector Summary'!$B$1="Weekly",F15/D15-1,F15/E15-1)),"") | H15: =IFERROR(SUMPRODUCT(($A$14:$A$23=A15)*($G$14:$G$23>G15))+1,"") -> 1 | I15: =A15&"|"&H15 -> IT|1
A16: IT | B16: HCLTECH | C16: 0 | D16: 0 | E16: 0 | F16: 0 | G16: =IFERROR(IF('Sector Summary'!$B$1="Daily",F16/C16-1,IF('Sector Summary'!$B$1="Weekly",F16/D16-1,F16/E16-1)),"") | H16: =IFERROR(SUMPRODUCT(($A$14:$A$23=A16)*($G$14:$G$23>G16))+1,"") -> 1 | I16: =A16&"|"&H16 -> IT|1
A17: IT | B17: WIPRO | C17: 0 | D17: 0 | E17: 0 | F17: 0 | G17: =IFERROR(IF('Sector Summary'!$B$1="Daily",F17/C17-1,IF('Sector Summary'!$B$1="Weekly",F17/D17-1,F17/E17-1)),"") | H17: =IFERROR(SUMPRODUCT(($A$14:$A$23=A17)*($G$14:$G$23>G17))+1,"") -> 1 | I17: =A17&"|"&H17 -> IT|1
A18: IT | B18: TECHM | C18: 0 | D18: 0 | E18: 0 | F18: 0 | G18: =IFERROR(IF('Sector Summary'!$B$1="Daily",F18/C18-1,IF('Sector Summary'!$B$1="Weekly",F18/D18-1,F18/E18-1)),"") | H18: =IFERROR(SUMPRODUCT(($A$14:$A$23=A18)*($G$14:$G$23>G18))+1,"") -> 1 | I18: =A18&"|"&H18 -> IT|1
A19: IT | B19: LTIM | C19: 0 | D19: 0 | E19: 0 | F19: 0 | G19: =IFERROR(IF('Sector Summary'!$B$1="Daily",F19/C19-1,IF('Sector Summary'!$B$1="Weekly",F19/D19-1,F19/E19-1)),"") | H19: =IFERROR(SUMPRODUCT(($A$14:$A$23=A19)*($G$14:$G$23>G19))+1,"") -> 1 | I19: =A19&"|"&H19 -> IT|1
A20: IT | B20: PERSISTENT | C20: 0 | D20: 0 | E20: 0 | F20: 0 | G20: =IFERROR(IF('Sector Summary'!$B$1="Daily",F20/C20-1,IF('Sector Summary'!$B$1="Weekly",F20/D20-1,F20/E20-1)),"") | H20: =IFERROR(SUMPRODUCT(($A$14:$A$23=A20)*($G$14:$G$23>G20))+1,"") -> 1 | I20: =A20&"|"&H20 -> IT|1
A21: IT | B21: COFORGE | C21: 0 | D21: 0 | E21: 0 | F21: 0 | G21: =IFERROR(IF('Sector Summary'!$B$1="Daily",F21/C21-1,IF('Sector Summary'!$B$1="Weekly",F21/D21-1,F21/E21-1)),"") | H21: =IFERROR(SUMPRODUCT(($A$14:$A$23=A21)*($G$14:$G$23>G21))+1,"") -> 1 | I21: =A21&"|"&H21 -> IT|1
A22: IT | B22: MPHASIS | C22: 0 | D22: 0 | E22: 0 | F22: 0 | G22: =IFERROR(IF('Sector Summary'!$B$1="Daily",F22/C22-1,IF('Sector Summary'!$B$1="Weekly",F22/D22-1,F22/E22-1)),"") | H22: =IFERROR(SUMPRODUCT(($A$14:$A$23=A22)*($G$14:$G$23>G22))+1,"") -> 1 | I22: =A22&"|"&H22 -> IT|1
A23: IT | B23: LTTS | C23: 0 | D23: 0 | E23: 0 | F23: 0 | G23: =IFERROR(IF('Sector Summary'!$B$1="Daily",F23/C23-1,IF('Sector Summary'!$B$1="Weekly",F23/D23-1,F23/E23-1)),"") | H23: =IFERROR(SUMPRODUCT(($A$14:$A$23=A23)*($G$14:$G$23>G23))+1,"") -> 1 | I23: =A23&"|"&H23 -> IT|1
A24: Auto | B24: MARUTI | C24: 0 | D24: 0 | E24: 0 | F24: 0 | G24: =IFERROR(IF('Sector Summary'!$B$1="Daily",F24/C24-1,IF('Sector Summary'!$B$1="Weekly",F24/D24-1,F24/E24-1)),"") | H24: =IFERROR(SUMPRODUCT(($A$24:$A$35=A24)*($G$24:$G$35>G24))+1,"") -> 1 | I24: =A24&"|"&H24 -> Auto|1
A25: Auto | B25: M&M | C25: 0 | D25: 0 | E25: 0 | F25: 0 | G25: =IFERROR(IF('Sector Summary'!$B$1="Daily",F25/C25-1,IF('Sector Summary'!$B$1="Weekly",F25/D25-1,F25/E25-1)),"") | H25: =IFERROR(SUMPRODUCT(($A$24:$A$35=A25)*($G$24:$G$35>G25))+1,"") -> 1 | I25: =A25&"|"&H25 -> Auto|1
A26: Auto | B26: TATAMOTORS | C26: 0 | D26: 0 | E26: 0 | F26: 0 | G26: =IFERROR(IF('Sector Summary'!$B$1="Daily",F26/C26-1,IF('Sector Summary'!$B$1="Weekly",F26/D26-1,F26/E26-1)),"") | H26: =IFERROR(SUMPRODUCT(($A$24:$A$35=A26)*($G$24:$G$35>G26))+1,"") -> 1 | I26: =A26&"|"&H26 -> Auto|1
A27: Auto | B27: BAJAJ-AUTO | C27: 0 | D27: 0 | E27: 0 | F27: 0 | G27: =IFERROR(IF('Sector Summary'!$B$1="Daily",F27/C27-1,IF('Sector Summary'!$B$1="Weekly",F27/D27-1,F27/E27-1)),"") | H27: =IFERROR(SUMPRODUCT(($A$24:$A$35=A27)*($G$24:$G$35>G27))+1,"") -> 1 | I27: =A27&"|"&H27 -> Auto|1
A28: Auto | B28: EICHERMOT | C28: 0 | D28: 0 | E28: 0 | F28: 0 | G28: =IFERROR(IF('Sector Summary'!$B$1="Daily",F28/C28-1,IF('Sector Summary'!$B$1="Weekly",F28/D28-1,F28/E28-1)),"") | H28: =IFERROR(SUMPRODUCT(($A$24:$A$35=A28)*($G$24:$G$35>G28))+1,"") -> 1 | I28: =A28&"|"&H28 -> Auto|1
A29: Auto | B29: HEROMOTOCO | C29: 0 | D29: 0 | E29: 0 | F29: 0 | G29: =IFERROR(IF('Sector Summary'!$B$1="Daily",F29/C29-1,IF('Sector Summary'!$B$1="Weekly",F29/D29-1,F29/E29-1)),"") | H29: =IFERROR(SUMPRODUCT(($A$24:$A$35=A29)*($G$24:$G$35>G29))+1,"") -> 1 | I29: =A29&"|"&H29 -> Auto|1
A30: Auto | B30: TVSMOTOR | C30: 0 | D30: 0 | E30: 0 | F30: 0 | G30: =IFERROR(IF('Sector Summary'!$B$1="Daily",F30/C30-1,IF('Sector Summary'!$B$1="Weekly",F30/D30-1,F30/E30-1)),"") | H30: =IFERROR(SUMPRODUCT(($A$24:$A$35=A30)*($G$24:$G$35>G30))+1,"") -> 1 | I30: =A30&"|"&H30 -> Auto|1
A31: Auto | B31: ASHOKLEY | C31: 0 | D31: 0 | E31: 0 | F31: 0 | G31: =IFERROR(IF('Sector Summary'!$B$1="Daily",F31/C31-1,IF('Sector Summary'!$B$1="Weekly",F31/D31-1,F31/E31-1)),"") | H31: =IFERROR(SUMPRODUCT(($A$24:$A$35=A31)*($G$24:$G$35>G31))+1,"") -> 1 | I31: =A31&"|"&H31 -> Auto|1
A32: Auto | B32: BHARATFORG | C32: 0 | D32: 0 | E32: 0 | F32: 0 | G32: =IFERROR(IF('Sector Summary'!$B$1="Daily",F32/C32-1,IF('Sector Summary'!$B$1="Weekly",F32/D32-1,F32/E32-1)),"") | H32: =IFERROR(SUMPRODUCT(($A$24:$A$35=A32)*($G$24:$G$35>G32))+1,"") -> 1 | I32: =A32&"|"&H32 -> Auto|1
A33: Auto | B33: MRF | C33: 0 | D33: 0 | E33: 0 | F33: 0 | G33: =IFERROR(IF('Sector Summary'!$B$1="Daily",F33/C33-1,IF('Sector Summary'!$B$1="Weekly",F33/D33-1,F33/E33-1)),"") | H33: =IFERROR(SUMPRODUCT(($A$24:$A$35=A33)*($G$24:$G$35>G33))+1,"") -> 1 | I33: =A33&"|"&H33 -> Auto|1
A34: Auto | B34: BOSCHLTD | C34: 0 | D34: 0 | E34: 0 | F34: 0 | G34: =IFERROR(IF('Sector Summary'!$B$1="Daily",F34/C34-1,IF('Sector Summary'!$B$1="Weekly",F34/D34-1,F34/E34-1)),"") | H34: =IFERROR(SUMPRODUCT(($A$24:$A$35=A34)*($G$24:$G$35>G34))+1,"") -> 1 | I34: =A34&"|"&H34 -> Auto|1
A35: Auto | B35: BALKRISIND | C35: 0 | D35: 0 | E35: 0 | F35: 0 | G35: =IFERROR(IF('Sector Summary'!$B$1="Daily",F35/C35-1,IF('Sector Summary'!$B$1="Weekly",F35/D35-1,F35/E35-1)),"") | H35: =IFERROR(SUMPRODUCT(($A$24:$A$35=A35)*($G$24:$G$35>G35))+1,"") -> 1 | I35: =A35&"|"&H35 -> Auto|1
A36: Pharma | B36: SUNPHARMA | C36: 0 | D36: 0 | E36: 0 | F36: 0 | G36: =IFERROR(IF('Sector Summary'!$B$1="Daily",F36/C36-1,IF('Sector Summary'!$B$1="Weekly",F36/D36-1,F36/E36-1)),"") | H36: =IFERROR(SUMPRODUCT(($A$36:$A$47=A36)*($G$36:$G$47>G36))+1,"") -> 1 | I36: =A36&"|"&H36 -> Pharma|1
A37: Pharma | B37: DRREDDY | C37: 0 | D37: 0 | E37: 0 | F37: 0 | G37: =IFERROR(IF('Sector Summary'!$B$1="Daily",F37/C37-1,IF('Sector Summary'!$B$1="Weekly",F37/D37-1,F37/E37-1)),"") | H37: =IFERROR(SUMPRODUCT(($A$36:$A$47=A37)*($G$36:$G$47>G37))+1,"") -> 1 | I37: =A37&"|"&H37 -> Pharma|1
A38: Pharma | B38: CIPLA | C38: 0 | D38: 0 | E38: 0 | F38: 0 | G38: =IFERROR(IF('Sector Summary'!$B$1="Daily",F38/C38-1,IF('Sector Summary'!$B$1="Weekly",F38/D38-1,F38/E38-1)),"") | H38: =IFERROR(SUMPRODUCT(($A$36:$A$47=A38)*($G$36:$G$47>G38))+1,"") -> 1 | I38: =A38&"|"&H38 -> Pharma|1
A39: Pharma | B39: DIVISLAB | C39: 0 | D39: 0 | E39: 0 | F39: 0 | G39: =IFERROR(IF('Sector Summary'!$B$1="Daily",F39/C39-1,IF('Sector Summary'!$B$1="Weekly",F39/D39-1,F39/E39-1)),"") | H39: =IFERROR(SUMPRODUCT(($A$36:$A$47=A39)*($G$36:$G$47>G39))+1,"") -> 1 | I39: =A39&"|"&H39 -> Pharma|1
A40: Pharma | B40: LUPIN | C40: 0 | D40: 0 | E40: 0 | F40: 0 | G40: =IFERROR(IF('Sector Summary'!$B$1="Daily",F40/C40-1,IF('Sector Summary'!$B$1="Weekly",F40/D40-1,F40/E40-1)),"") | H40: =IFERROR(SUMPRODUCT(($A$36:$A$47=A40)*($G$36:$G$47>G40))+1,"") -> 1 | I40: =A40&"|"&H40 -> Pharma|1
...

Sheet Drilldown
A1: Select Sector: | B1: Bank | C1: <- pick a sector (dropdown) | H1: TotalMembers
A2: Active Timeframe: | B2: ='Sector Summary'!$B$1 -> Daily | C2: <- set on 'Sector Summary' tab, shared everywhere | H2: =COUNTIF(Constituents!$A:$A,$B$1) -> 12
A4: Best performer: | B4: =IFERROR(INDEX(B9:B24,MATCH(1,A9:A24,0))&" ("&TEXT(INDEX(D9:D24,1),"0.00%")&")","") -> PNB (1.37%)
A5: Worst performer: | B5: =IFERROR(INDEX(B9:B24,MATCH($H$2,A9:A24,0))&" ("&TEXT(INDEX(D9:D24,MATCH($H$2,A9:A24,0)),"0.00%")&")","") -> INDUSINDBK (-1.41%)
A8: Rank | B8: Symbol | C8: LTP | D8: % Chg (Active)
A9: 1 | B9: =IFERROR(INDEX(Constituents!$B:$B,MATCH($B$1&"|"&A9,Constituents!$I:$I,0)),"") -> PNB | C9: =IFERROR(INDEX(Constituents!$F:$F,MATCH($B$1&"|"&A9,Constituents!$I:$I,0)),"") -> 103.75 | D9: =IFERROR(INDEX(Constituents!$G:$G,MATCH($B$1&"|"&A9,Constituents!$I:$I,0)),"") -> 0.013678554
A10: 2 | B10: =IFERROR(INDEX(Constituents!$B:$B,MATCH($B$1&"|"&A10,Constituents!$I:$I,0)),"") -> AUBANK | C10: =IFERROR(INDEX(Constituents!$F:$F,MATCH($B$1&"|"&A10,Constituents!$I:$I,0)),"") -> 651.2 | D10: =IFERROR(INDEX(Constituents!$G:$G,MATCH($B$1&"|"&A10,Constituents!$I:$I,0)),"") -> 0.013540856
A11: 3 | B11: =IFERROR(INDEX(Constituents!$B:$B,MATCH($B$1&"|"&A11,Constituents!$I:$I,0)),"") -> FEDERALBNK | C11: =IFERROR(INDEX(Constituents!$F:$F,MATCH($B$1&"|"&A11,Constituents!$I:$I,0)),"") -> 199.3 | D11: =IFERROR(INDEX(Constituents!$G:$G,MATCH($B$1&"|"&A11,Constituents!$I:$I,0)),"") -> 0.013218099
A12: 4 | B12: =IFERROR(INDEX(Constituents!$B:$B,MATCH($B$1&"|"&A12,Constituents!$I:$I,0)),"") -> CANBK | C12: =IFERROR(INDEX(Constituents!$F:$F,MATCH($B$1&"|"&A12,Constituents!$I:$I,0)),"") -> 99.9 | D12: =IFERROR(INDEX(Constituents!$G:$G,MATCH($B$1&"|"&A12,Constituents!$I:$I,0)),"") -> 0.013184584
A13: 5 | B13: =IFERROR(INDEX(Constituents!$B:$B,MATCH($B$1&"|"&A13,Constituents!$I:$I,0)),"") -> BANKBARODA | C13: =IFERROR(INDEX(Constituents!$F:$F,MATCH($B$1&"|"&A13,Constituents!$I:$I,0)),"") -> 240.9 | D13: =IFERROR(INDEX(Constituents!$G:$G,MATCH($B$1&"|"&A13,Constituents!$I:$I,0)),"") -> 0.011547344
A14: 6 | B14: =IFERROR(INDEX(Constituents!$B:$B,MATCH($B$1&"|"&A14,Constituents!$I:$I,0)),"") -> SBIN | C14: =IFERROR(INDEX(Constituents!$F:$F,MATCH($B$1&"|"&A14,Constituents!$I:$I,0)),"") -> 826.9 | D14: =IFERROR(INDEX(Constituents!$G:$G,MATCH($B$1&"|"&A14,Constituents!$I:$I,0)),"") -> 0.010447852
A15: 7 | B15: =IFERROR(INDEX(Constituents!$B:$B,MATCH($B$1&"|"&A15,Constituents!$I:$I,0)),"") -> ICICIBANK | C15: =IFERROR(INDEX(Constituents!$F:$F,MATCH($B$1&"|"&A15,Constituents!$I:$I,0)),"") -> 1223.6 | D15: =IFERROR(INDEX(Constituents!$G:$G,MATCH($B$1&"|"&A15,Constituents!$I:$I,0)),"") -> 0.010070992
A16: 8 | B16: =IFERROR(INDEX(Constituents!$B:$B,MATCH($B$1&"|"&A16,Constituents!$I:$I,0)),"") -> IDFCFIRSTB | C16: =IFERROR(INDEX(Constituents!$F:$F,MATCH($B$1&"|"&A16,Constituents!$I:$I,0)),"") -> 73.1 | D16: =IFERROR(INDEX(Constituents!$G:$G,MATCH($B$1&"|"&A16,Constituents!$I:$I,0)),"") -> 0.0096685083
A17: 9 | B17: =IFERROR(INDEX(Constituents!$B:$B,MATCH($B$1&"|"&A17,Constituents!$I:$I,0)),"") -> AXISBANK | C17: =IFERROR(INDEX(Constituents!$F:$F,MATCH($B$1&"|"&A17,Constituents!$I:$I,0)),"") -> 1163.55 | D17: =IFERROR(INDEX(Constituents!$G:$G,MATCH($B$1&"|"&A17,Constituents!$I:$I,0)),"") -> 0.0093251214
A18: 10 | B18: =IFERROR(INDEX(Constituents!$B:$B,MATCH($B$1&"|"&A18,Constituents!$I:$I,0)),"") -> HDFCBANK | C18: =IFERROR(INDEX(Constituents!$F:$F,MATCH($B$1&"|"&A18,Constituents!$I:$I,0)),"") -> 1657.85 | D18: =IFERROR(INDEX(Constituents!$G:$G,MATCH($B$1&"|"&A18,Constituents!$I:$I,0)),"") -> 0.005854872
A19: 11 | B19: =IFERROR(INDEX(Constituents!$B:$B,MATCH($B$1&"|"&A19,Constituents!$I:$I,0)),"") -> KOTAKBANK | C19: =IFERROR(INDEX(Constituents!$F:$F,MATCH($B$1&"|"&A19,Constituents!$I:$I,0)),"") -> 1771.25 | D19: =IFERROR(INDEX(Constituents!$G:$G,MATCH($B$1&"|"&A19,Constituents!$I:$I,0)),"") -> -0.010253688
A20: 12 | B20: =IFERROR(INDEX(Constituents!$B:$B,MATCH($B$1&"|"&A20,Constituents!$I:$I,0)),"") -> INDUSINDBK | C20: =IFERROR(INDEX(Constituents!$F:$F,MATCH($B$1&"|"&A20,Constituents!$I:$I,0)),"") -> 998.1 | D20: =IFERROR(INDEX(Constituents!$G:$G,MATCH($B$1&"|"&A20,Constituents!$I:$I,0)),"") -> -0.014124852
... A24: 16 | B24: =IFERROR(INDEX(Constituents!$B:$B,MATCH($B$1&"|"&A24,Constituents!$I:$I,0)),"") | C24: =IFERROR(INDEX(Constituents!$F:$F,MATCH($B$1&"|"&A24,Constituents!$I:$I,0)),"") | D24: =IFERROR(INDEX(Constituents!$G:$G,MATCH($B$1&"|"&A24,Constituents!$I:$I,0)),"")
